I'm sorry, but an uncaught exception occurred.

While running game code:
  File "game/script.rpy", line 3261, in script
    tf """
Exception: Sayer 'tf' is not defined.

-- Full Traceback ------------------------------------------------------------

Full traceback:
  File "game/script.rpy", line 3261, in script
    tf """
  File "C:\Users\thoma\OneDrive\Desktop\Renpy\renpy\ast.py", line 678, in execute
    who = eval_who(self.who, self.who_fast)
  File "C:\Users\thoma\OneDrive\Desktop\Renpy\renpy\ast.py", line 576, in eval_who
    raise Exception("Sayer '%s' is not defined." % who.encode("utf-8"))
Exception: Sayer 'tf' is not defined.

Windows-8-6.2.9200
Ren'Py 7.3.5.606
Beyond the Window 
Mon Jul 13 20:59:59 2020
